Traceback (most recent call last):
  File "/home/pi/pfs-rewrite/lib/exceptions.py", line 103, in wrapper
    return func(*args, **kwargs)
  File "/home/pi/pfs-rewrite/lib/registry.py", line 73, in encode
    sum([1 << index for index in range(len(StateFieldRegistry.COMPONENTS))
  File "/home/pi/pfs-rewrite/lib/registry.py", line 74, in <listcomp>
    if StateFieldRegistry.COMPONENTS[index] in self.vars.LOCKED_ON_DEVICES]),
AttributeError: 'Vars' object has no attribute 'vars'

During handling of the above exception, another exception occurred:

Traceback (most recent call last):
  File "/home/pi/pfs-rewrite/mission_control.py", line 52, in main
    self.mcl.iterate()  # Run a single iteration of MCL
  File "/home/pi/pfs-rewrite/lib/exceptions.py", line 103, in wrapper
    return func(*args, **kwargs)
  File "/home/pi/pfs-rewrite/MainControlLoop/main_control_loop.py", line 47, in iterate
    self.sfr.logger.log()  # Logs data
  File "/home/pi/pfs-rewrite/lib/exceptions.py", line 103, in wrapper
    return func(*args, **kwargs)
  File "/home/pi/pfs-rewrite/lib/log.py", line 99, in log
    self.loggers[i].execute()
  File "/home/pi/pfs-rewrite/lib/exceptions.py", line 103, in wrapper
    return func(*args, **kwargs)
  File "/home/pi/pfs-rewrite/lib/clock.py", line 24, in execute
    result = self.func()  # Run function, return whether it ran
  File "/home/pi/pfs-rewrite/lib/exceptions.py", line 103, in wrapper
    return func(*args, **kwargs)
  File "/home/pi/pfs-rewrite/lib/registry.py", line 321, in dump
    self.logs["sfr_readable"].write(self.vars.to_dict())
  File "/home/pi/pfs-rewrite/lib/exceptions.py", line 103, in wrapper
    return func(*args, **kwargs)
  File "/home/pi/pfs-rewrite/lib/registry.py", line 93, in to_dict
    encoded = self.encode()
  File "/home/pi/pfs-rewrite/lib/exceptions.py", line 107, in wrapper
    raise exception(e)  # Wrap with given exception
lib.exceptions.LogicalError: 'Vars' object has no attribute 'vars'

During handling of the above exception, another exception occurred:

Traceback (most recent call last):
  File "/home/pi/pfs-rewrite/lib/exceptions.py", line 103, in wrapper
    return func(*args, **kwargs)
  File "/home/pi/pfs-rewrite/lib/registry.py", line 73, in encode
    sum([1 << index for index in range(len(StateFieldRegistry.COMPONENTS))
  File "/home/pi/pfs-rewrite/lib/registry.py", line 74, in <listcomp>
    if StateFieldRegistry.COMPONENTS[index] in self.vars.LOCKED_ON_DEVICES]),
AttributeError: 'Vars' object has no attribute 'vars'

During handling of the above exception, another exception occurred:

Traceback (most recent call last):
  File "/home/pi/pfs-rewrite/mission_control.py", line 211, in <module>
    mission_control.main()
  File "/home/pi/pfs-rewrite/mission_control.py", line 72, in main
    self.testing_mode(e)
  File "/home/pi/pfs-rewrite/mission_control.py", line 132, in testing_mode
    print(self.sfr.vars.to_dict())
  File "/home/pi/pfs-rewrite/lib/exceptions.py", line 103, in wrapper
    return func(*args, **kwargs)
  File "/home/pi/pfs-rewrite/lib/registry.py", line 93, in to_dict
    encoded = self.encode()
  File "/home/pi/pfs-rewrite/lib/exceptions.py", line 107, in wrapper
    raise exception(e)  # Wrap with given exception
lib.exceptions.LogicalError: 'Vars' object has no attribute 'vars'
